2025-08-25 21:30:48 [ERROR] networksecurity: Error occurred in python script [C:\Users\anjali\Desktop\Network_Security_System\push_data.py] line [63] \u2192 mongodb_url:27017: [Errno 11001] getaddrinfo failed (configured timeouts: socketTimeoutMS: 20000.0ms, connectTimeoutMS: 20000.0ms), Timeout: 30s, Topology Description: <TopologyDescription id: 68ac88927c2d764758f41171, topology_type: Unknown, servers: [<ServerDescription ('mongodb_url', 27017) server_type: Unknown, rtt: None, error=AutoReconnect('mongodb_url:27017: [Errno 11001] getaddrinfo failed (configured timeouts: socketTimeoutMS: 20000.0ms, connectTimeoutMS: 20000.0ms)')>]>
